Workbook

Sheet Offers
A1: S.No | B1: Register No | C1: Name | D1: Department | E1: Company Name | F1: Salary Package (LPA) | G1: Internship Status | H1: Internship Mode | I1: Type | J1: Allowing Status | K1: Email ID | L1: Student Contact No | M1: Organized by | N1: Offer Entry Date | O1: Joined Date | P1: Offered Date | Q1: Offer reference no. | R1: Is that Interncum Placement Offer? | S1: Appoinment Letter Date | T1: Appointment Letter reference no. | U1: Appoinment Letter - Proof Link | V1: Offer - Proof Link | W1: Mail Proof | X1: Internship Letter | Y1: Internship Cum Offer
A2: {=IF(B2:B986="","",ROW(B2:B986)-1)} -> 1 | B2: 7376232AD141 | C2: =IFERROR(__xludf.DUMMYFUNCTION("XLOOKUP(B2, IMPORTRANGE(""https://docs.google.com/spreadsheets/d/1UUC6R1hVFPCYDEbJMIXaIBW-jeQYiKTRixeKD_tUHGw/edit?gid=0#gid=0"", ""List!B:B""), IMPORTRANGE(""https://docs.google.com/spreadsheets/d/1UUC6R1hVFPCYDEbJMIXaIBW-jeQYiKTRixeKD_tUHGw/edit?gid=0#g"&"id=0"", ""List!C:C""), ""-"")"),"GOWRIPRASATH VENKATACHALAM") -> GOWRIPRASATH VENKATACHALAM | D2: =IFERROR(__xludf.DUMMYFUNCTION("XLOOKUP(B2, IMPORTRANGE(""https://docs.google.com/spreadsheets/d/1UUC6R1hVFPCYDEbJMIXaIBW-jeQYiKTRixeKD_tUHGw/edit?gid=0#gid=0"", ""List!B:B""), IMPORTRANGE(""https://docs.google.com/spreadsheets/d/1UUC6R1hVFPCYDEbJMIXaIBW-jeQYiKTRixeKD_tUHGw/edit?gid=0#g"&"id=0"", ""List!D:D""), ""-"")"),"ARTIFICIAL INTELLIGENCE AND DATA SCIENCE") -> ARTIFICIAL INTELLIGENCE AND DATA SCIENCE | E2: Conversight.Ai | F2: 5 | G2: Joined | H2: Offline | I2: ITP | J2: Allow for Double the package | K2: =IFERROR(__xludf.DUMMYFUNCTION("XLOOKUP(B2, IMPORTRANGE(""https://docs.google.com/spreadsheets/d/1GpX_8hJc54hBz8KrakqcWdiXAS6pjY1zWE_9fWBXnEM/edit?gid=1460649486#gid=1460649486"", ""List!B:B""), IMPORTRANGE(""https://docs.google.com/spreadsheets/d/1GpX_8hJc54hBz8KrakqcWdiXAS6pjY1zWE_9fW"&"BXnEM/edit?gid=1460649486#gid=1460649486"", ""List!E:E""), ""-"")"),"gowriprasath.ad23@bitsathy.ac.in") -> gowriprasath.ad23@bitsathy.ac.in | L2: =IFERROR(__xludf.DUMMYFUNCTION("XLOOKUP(B2, IMPORTRANGE(""https://docs.google.com/spreadsheets/d/1GpX_8hJc54hBz8KrakqcWdiXAS6pjY1zWE_9fWBXnEM/edit?gid=1460649486#gid=1460649486"", ""List!B:B""), IMPORTRANGE(""https://docs.google.com/spreadsheets/d/1GpX_8hJc54hBz8KrakqcWdiXAS6pjY1zWE_9fW"&"BXnEM/edit?gid=1460649486#gid=1460649486"", ""List!G:G""), ""-"")"),"9597932727") -> 9597932727 | M2: T&P | N2: 26.12.2025 | O2: 05.01.2026 | R2: YES
A3: 2 | B3: 7376232AD155 | C3: =IFERROR(__xludf.DUMMYFUNCTION("XLOOKUP(B3, IMPORTRANGE(""https://docs.google.com/spreadsheets/d/1UUC6R1hVFPCYDEbJMIXaIBW-jeQYiKTRixeKD_tUHGw/edit?gid=0#gid=0"", ""List!B:B""), IMPORTRANGE(""https://docs.google.com/spreadsheets/d/1UUC6R1hVFPCYDEbJMIXaIBW-jeQYiKTRixeKD_tUHGw/edit?gid=0#g"&"id=0"", ""List!C:C""), ""-"")"),"HARSHIKA M") -> HARSHIKA M | D3: =IFERROR(__xludf.DUMMYFUNCTION("XLOOKUP(B3, IMPORTRANGE(""https://docs.google.com/spreadsheets/d/1UUC6R1hVFPCYDEbJMIXaIBW-jeQYiKTRixeKD_tUHGw/edit?gid=0#gid=0"", ""List!B:B""), IMPORTRANGE(""https://docs.google.com/spreadsheets/d/1UUC6R1hVFPCYDEbJMIXaIBW-jeQYiKTRixeKD_tUHGw/edit?gid=0#g"&"id=0"", ""List!D:D""), ""-"")"),"ARTIFICIAL INTELLIGENCE AND DATA SCIENCE") -> ARTIFICIAL INTELLIGENCE AND DATA SCIENCE | E3: Conversight.Ai | F3: 5 | G3: Joined | H3: Offline | I3: ITP | J3: Allow for Double the package | K3: =IFERROR(__xludf.DUMMYFUNCTION("XLOOKUP(B3, IMPORTRANGE(""https://docs.google.com/spreadsheets/d/1GpX_8hJc54hBz8KrakqcWdiXAS6pjY1zWE_9fWBXnEM/edit?gid=1460649486#gid=1460649486"", ""List!B:B""), IMPORTRANGE(""https://docs.google.com/spreadsheets/d/1GpX_8hJc54hBz8KrakqcWdiXAS6pjY1zWE_9fW"&"BXnEM/edit?gid=1460649486#gid=1460649486"", ""List!E:E""), ""-"")"),"harshika.ad23@bitsathy.ac.in") -> harshika.ad23@bitsathy.ac.in | L3: =IFERROR(__xludf.DUMMYFUNCTION("XLOOKUP(B3, IMPORTRANGE(""https://docs.google.com/spreadsheets/d/1GpX_8hJc54hBz8KrakqcWdiXAS6pjY1zWE_9fWBXnEM/edit?gid=1460649486#gid=1460649486"", ""List!B:B""), IMPORTRANGE(""https://docs.google.com/spreadsheets/d/1GpX_8hJc54hBz8KrakqcWdiXAS6pjY1zWE_9fW"&"BXnEM/edit?gid=1460649486#gid=1460649486"", ""List!G:G""), ""-"")"),"8838239950") -> 8838239950 | M3: T&P | N3: 26.12.2025 | O3: 05.01.2026 | R3: YES
A4: 3 | B4: 7376232IT114 | C4: =IFERROR(__xludf.DUMMYFUNCTION("XLOOKUP(B4, IMPORTRANGE(""https://docs.google.com/spreadsheets/d/1UUC6R1hVFPCYDEbJMIXaIBW-jeQYiKTRixeKD_tUHGw/edit?gid=0#gid=0"", ""List!B:B""), IMPORTRANGE(""https://docs.google.com/spreadsheets/d/1UUC6R1hVFPCYDEbJMIXaIBW-jeQYiKTRixeKD_tUHGw/edit?gid=0#g"&"id=0"", ""List!C:C""), ""-"")"),"ARVINDH S") -> ARVINDH S | D4: =IFERROR(__xludf.DUMMYFUNCTION("XLOOKUP(B4, IMPORTRANGE(""https://docs.google.com/spreadsheets/d/1UUC6R1hVFPCYDEbJMIXaIBW-jeQYiKTRixeKD_tUHGw/edit?gid=0#gid=0"", ""List!B:B""), IMPORTRANGE(""https://docs.google.com/spreadsheets/d/1UUC6R1hVFPCYDEbJMIXaIBW-jeQYiKTRixeKD_tUHGw/edit?gid=0#g"&"id=0"", ""List!D:D""), ""-"")"),"INFORMATION TECHNOLOGY") -> INFORMATION TECHNOLOGY | E4: Conversight.Ai | F4: 5 | G4: Joined | H4: Offline | I4: ITP | J4: Allow for Double the package | K4: =IFERROR(__xludf.DUMMYFUNCTION("XLOOKUP(B4, IMPORTRANGE(""https://docs.google.com/spreadsheets/d/1GpX_8hJc54hBz8KrakqcWdiXAS6pjY1zWE_9fWBXnEM/edit?gid=1460649486#gid=1460649486"", ""List!B:B""), IMPORTRANGE(""https://docs.google.com/spreadsheets/d/1GpX_8hJc54hBz8KrakqcWdiXAS6pjY1zWE_9fW"&"BXnEM/edit?gid=1460649486#gid=1460649486"", ""List!E:E""), ""-"")"),"arvindh.it23@bitsathy.ac.in") -> arvindh.it23@bitsathy.ac.in | L4: =IFERROR(__xludf.DUMMYFUNCTION("XLOOKUP(B4, IMPORTRANGE(""https://docs.google.com/spreadsheets/d/1GpX_8hJc54hBz8KrakqcWdiXAS6pjY1zWE_9fWBXnEM/edit?gid=1460649486#gid=1460649486"", ""List!B:B""), IMPORTRANGE(""https://docs.google.com/spreadsheets/d/1GpX_8hJc54hBz8KrakqcWdiXAS6pjY1zWE_9fW"&"BXnEM/edit?gid=1460649486#gid=1460649486"", ""List!G:G""), ""-"")"),"9626163456") -> 9626163456 | M4: T&P | N4: 26.12.2025 | O4: 05.01.2026 | R4: YES
A5: 4 | B5: 7376232AD213 | C5: =IFERROR(__xludf.DUMMYFUNCTION("XLOOKUP(B5, IMPORTRANGE(""https://docs.google.com/spreadsheets/d/1UUC6R1hVFPCYDEbJMIXaIBW-jeQYiKTRixeKD_tUHGw/edit?gid=0#gid=0"", ""List!B:B""), IMPORTRANGE(""https://docs.google.com/spreadsheets/d/1UUC6R1hVFPCYDEbJMIXaIBW-jeQYiKTRixeKD_tUHGw/edit?gid=0#g"&"id=0"", ""List!C:C""), ""-"")"),"PRANEETH K A") -> PRANEETH K A | D5: =IFERROR(__xludf.DUMMYFUNCTION("XLOOKUP(B5, IMPORTRANGE(""https://docs.google.com/spreadsheets/d/1UUC6R1hVFPCYDEbJMIXaIBW-jeQYiKTRixeKD_tUHGw/edit?gid=0#gid=0"", ""List!B:B""), IMPORTRANGE(""https://docs.google.com/spreadsheets/d/1UUC6R1hVFPCYDEbJMIXaIBW-jeQYiKTRixeKD_tUHGw/edit?gid=0#g"&"id=0"", ""List!D:D""), ""-"")"),"ARTIFICIAL INTELLIGENCE AND DATA SCIENCE") -> ARTIFICIAL INTELLIGENCE AND DATA SCIENCE | E5: Conversight.Ai | F5: 5 | G5: Joined | H5: Offline | I5: ITP | J5: Allow for Double the package | K5: =IFERROR(__xludf.DUMMYFUNCTION("XLOOKUP(B5, IMPORTRANGE(""https://docs.google.com/spreadsheets/d/1GpX_8hJc54hBz8KrakqcWdiXAS6pjY1zWE_9fWBXnEM/edit?gid=1460649486#gid=1460649486"", ""List!B:B""), IMPORTRANGE(""https://docs.google.com/spreadsheets/d/1GpX_8hJc54hBz8KrakqcWdiXAS6pjY1zWE_9fW"&"BXnEM/edit?gid=1460649486#gid=1460649486"", ""List!E:E""), ""-"")"),"praneeth.ad23@bitsathy.ac.in") -> praneeth.ad23@bitsathy.ac.in | L5: =IFERROR(__xludf.DUMMYFUNCTION("XLOOKUP(B5, IMPORTRANGE(""https://docs.google.com/spreadsheets/d/1GpX_8hJc54hBz8KrakqcWdiXAS6pjY1zWE_9fWBXnEM/edit?gid=1460649486#gid=1460649486"", ""List!B:B""), IMPORTRANGE(""https://docs.google.com/spreadsheets/d/1GpX_8hJc54hBz8KrakqcWdiXAS6pjY1zWE_9fW"&"BXnEM/edit?gid=1460649486#gid=1460649486"", ""List!G:G""), ""-"")"),"6379508939") -> 6379508939 | M5: T&P | N5: 26.12.2025 | O5: 05.01.2026 | R5: YES
A6: 5 | B6: 7376232IT221 | C6: =IFERROR(__xludf.DUMMYFUNCTION("XLOOKUP(B6, IMPORTRANGE(""https://docs.google.com/spreadsheets/d/1UUC6R1hVFPCYDEbJMIXaIBW-jeQYiKTRixeKD_tUHGw/edit?gid=0#gid=0"", ""List!B:B""), IMPORTRANGE(""https://docs.google.com/spreadsheets/d/1UUC6R1hVFPCYDEbJMIXaIBW-jeQYiKTRixeKD_tUHGw/edit?gid=0#g"&"id=0"", ""List!C:C""), ""-"")"),"PRANAOV NAATH S P") -> PRANAOV NAATH S P | D6: =IFERROR(__xludf.DUMMYFUNCTION("XLOOKUP(B6, IMPORTRANGE(""https://docs.google.com/spreadsheets/d/1UUC6R1hVFPCYDEbJMIXaIBW-jeQYiKTRixeKD_tUHGw/edit?gid=0#gid=0"", ""List!B:B""), IMPORTRANGE(""https://docs.google.com/spreadsheets/d/1UUC6R1hVFPCYDEbJMIXaIBW-jeQYiKTRixeKD_tUHGw/edit?gid=0#g"&"id=0"", ""List!D:D""), ""-"")"),"INFORMATION TECHNOLOGY") -> INFORMATION TECHNOLOGY | E6: Conversight.Ai | F6: 5 | G6: Joined | H6: Offline | I6: ITP | J6: Allow | K6: =IFERROR(__xludf.DUMMYFUNCTION("XLOOKUP(B6, IMPORTRANGE(""https://docs.google.com/spreadsheets/d/1GpX_8hJc54hBz8KrakqcWdiXAS6pjY1zWE_9fWBXnEM/edit?gid=1460649486#gid=1460649486"", ""List!B:B""), IMPORTRANGE(""https://docs.google.com/spreadsheets/d/1GpX_8hJc54hBz8KrakqcWdiXAS6pjY1zWE_9fW"&"BXnEM/edit?gid=1460649486#gid=1460649486"", ""List!E:E""), ""-"")"),"pranaovnaath.it23@bitsathy.ac.in") -> pranaovnaath.it23@bitsathy.ac.in | L6: =IFERROR(__xludf.DUMMYFUNCTION("XLOOKUP(B6, IMPORTRANGE(""https://docs.google.com/spreadsheets/d/1GpX_8hJc54hBz8KrakqcWdiXAS6pjY1zWE_9fWBXnEM/edit?gid=1460649486#gid=1460649486"", ""List!B:B""), IMPORTRANGE(""https://docs.google.com/spreadsheets/d/1GpX_8hJc54hBz8KrakqcWdiXAS6pjY1zWE_9fW"&"BXnEM/edit?gid=1460649486#gid=1460649486"", ""List!G:G""), ""-"")"),"9865068750") -> 9865068750 | M6: T&P | N6: 26.12.2025 | O6: 05.01.2026 | R6: YES
A7: 6 | B7: 7376231CD121 | C7: =IFERROR(__xludf.DUMMYFUNCTION("XLOOKUP(B7, IMPORTRANGE(""https://docs.google.com/spreadsheets/d/1UUC6R1hVFPCYDEbJMIXaIBW-jeQYiKTRixeKD_tUHGw/edit?gid=0#gid=0"", ""List!B:B""), IMPORTRANGE(""https://docs.google.com/spreadsheets/d/1UUC6R1hVFPCYDEbJMIXaIBW-jeQYiKTRixeKD_tUHGw/edit?gid=0#g"&"id=0"", ""List!C:C""), ""-"")"),"KAVYA M") -> KAVYA M | D7: =IFERROR(__xludf.DUMMYFUNCTION("XLOOKUP(B7, IMPORTRANGE(""https://docs.google.com/spreadsheets/d/1UUC6R1hVFPCYDEbJMIXaIBW-jeQYiKTRixeKD_tUHGw/edit?gid=0#gid=0"", ""List!B:B""), IMPORTRANGE(""https://docs.google.com/spreadsheets/d/1UUC6R1hVFPCYDEbJMIXaIBW-jeQYiKTRixeKD_tUHGw/edit?gid=0#g"&"id=0"", ""List!D:D""), ""-"")"),"COMPUTER SCIENCE AND DESIGN") -> COMPUTER SCIENCE AND DESIGN | E7: Conversight.Ai | F7: 5 | G7: Joined | H7: Offline | I7: ITP | J7: Allow for Double the package | K7: =IFERROR(__xludf.DUMMYFUNCTION("XLOOKUP(B7, IMPORTRANGE(""https://docs.google.com/spreadsheets/d/1GpX_8hJc54hBz8KrakqcWdiXAS6pjY1zWE_9fWBXnEM/edit?gid=1460649486#gid=1460649486"", ""List!B:B""), IMPORTRANGE(""https://docs.google.com/spreadsheets/d/1GpX_8hJc54hBz8KrakqcWdiXAS6pjY1zWE_9fW"&"BXnEM/edit?gid=1460649486#gid=1460649486"", ""List!E:E""), ""-"")"),"kavya.cd23@bitsathy.ac.in") -> kavya.cd23@bitsathy.ac.in | L7: =IFERROR(__xludf.DUMMYFUNCTION("XLOOKUP(B7, IMPORTRANGE(""https://docs.google.com/spreadsheets/d/1GpX_8hJc54hBz8KrakqcWdiXAS6pjY1zWE_9fWBXnEM/edit?gid=1460649486#gid=1460649486"", ""List!B:B""), IMPORTRANGE(""https://docs.google.com/spreadsheets/d/1GpX_8hJc54hBz8KrakqcWdiXAS6pjY1zWE_9fW"&"BXnEM/edit?gid=1460649486#gid=1460649486"", ""List!G:G""), ""-"")"),"9344256024") -> 9344256024 | M7: T&P | N7: 26.12.2025 | O7: 05.01.2026 | R7: YES
A8: 7 | B8: 7376231CS318 | C8: =IFERROR(__xludf.DUMMYFUNCTION("XLOOKUP(B8, IMPORTRANGE(""https://docs.google.com/spreadsheets/d/1UUC6R1hVFPCYDEbJMIXaIBW-jeQYiKTRixeKD_tUHGw/edit?gid=0#gid=0"", ""List!B:B""), IMPORTRANGE(""https://docs.google.com/spreadsheets/d/1UUC6R1hVFPCYDEbJMIXaIBW-jeQYiKTRixeKD_tUHGw/edit?gid=0#g"&"id=0"", ""List!C:C""), ""-"")"),"SREENIDHI R") -> SREENIDHI R | D8: =IFERROR(__xludf.DUMMYFUNCTION("XLOOKUP(B8, IMPORTRANGE(""https://docs.google.com/spreadsheets/d/1UUC6R1hVFPCYDEbJMIXaIBW-jeQYiKTRixeKD_tUHGw/edit?gid=0#gid=0"", ""List!B:B""), IMPORTRANGE(""https://docs.google.com/spreadsheets/d/1UUC6R1hVFPCYDEbJMIXaIBW-jeQYiKTRixeKD_tUHGw/edit?gid=0#g"&"id=0"", ""List!D:D""), ""-"")"),"COMPUTER SCIENCE AND ENGINEERING") -> COMPUTER SCIENCE AND ENGINEERING | E8: Conversight.Ai | F8: 5 | G8: Joined | H8: Offline | I8: ITP | J8: Allow for Double the package | K8: =IFERROR(__xludf.DUMMYFUNCTION("XLOOKUP(B8, IMPORTRANGE(""https://docs.google.com/spreadsheets/d/1GpX_8hJc54hBz8KrakqcWdiXAS6pjY1zWE_9fWBXnEM/edit?gid=1460649486#gid=1460649486"", ""List!B:B""), IMPORTRANGE(""https://docs.google.com/spreadsheets/d/1GpX_8hJc54hBz8KrakqcWdiXAS6pjY1zWE_9fW"&"BXnEM/edit?gid=1460649486#gid=1460649486"", ""List!E:E""), ""-"")"),"sreenidhi.cs23@bitsathy.ac.in") -> sreenidhi.cs23@bitsathy.ac.in | L8: =IFERROR(__xludf.DUMMYFUNCTION("XLOOKUP(B8, IMPORTRANGE(""https://docs.google.com/spreadsheets/d/1GpX_8hJc54hBz8KrakqcWdiXAS6pjY1zWE_9fWBXnEM/edit?gid=1460649486#gid=1460649486"", ""List!B:B""), IMPORTRANGE(""https://docs.google.com/spreadsheets/d/1GpX_8hJc54hBz8KrakqcWdiXAS6pjY1zWE_9fW"&"BXnEM/edit?gid=1460649486#gid=1460649486"", ""List!G:G""), ""-"")"),"7904611901") -> 7904611901 | M8: T&P | N8: 26.12.2025 | O8: 05.01.2026 | R8: YES
A9: 8 | B9: 7376231SE116 | C9: =IFERROR(__xludf.DUMMYFUNCTION("XLOOKUP(B9, IMPORTRANGE(""https://docs.google.com/spreadsheets/d/1UUC6R1hVFPCYDEbJMIXaIBW-jeQYiKTRixeKD_tUHGw/edit?gid=0#gid=0"", ""List!B:B""), IMPORTRANGE(""https://docs.google.com/spreadsheets/d/1UUC6R1hVFPCYDEbJMIXaIBW-jeQYiKTRixeKD_tUHGw/edit?gid=0#g"&"id=0"", ""List!C:C""), ""-"")"),"GAYATHIRI E") -> GAYATHIRI E | D9: =IFERROR(__xludf.DUMMYFUNCTION("XLOOKUP(B9, IMPORTRANGE(""https://docs.google.com/spreadsheets/d/1UUC6R1hVFPCYDEbJMIXaIBW-jeQYiKTRixeKD_tUHGw/edit?gid=0#gid=0"", ""List!B:B""), IMPORTRANGE(""https://docs.google.com/spreadsheets/d/1UUC6R1hVFPCYDEbJMIXaIBW-jeQYiKTRixeKD_tUHGw/edit?gid=0#g"&"id=0"", ""List!D:D""), ""-"")"),"INFORMATION SCIENCE AND ENGINEERING") -> INFORMATION SCIENCE AND ENGINEERING | E9: Soliton | F9: 10 | G9: Joined | H9: Online | I9: CORE | J9: Allow for Double the package | K9: =IFERROR(__xludf.DUMMYFUNCTION("XLOOKUP(B9, IMPORTRANGE(""https://docs.google.com/spreadsheets/d/1GpX_8hJc54hBz8KrakqcWdiXAS6pjY1zWE_9fWBXnEM/edit?gid=1460649486#gid=1460649486"", ""List!B:B""), IMPORTRANGE(""https://docs.google.com/spreadsheets/d/1GpX_8hJc54hBz8KrakqcWdiXAS6pjY1zWE_9fW"&"BXnEM/edit?gid=1460649486#gid=1460649486"", ""List!E:E""), ""-"")"),"gayathiri.se23@bitsathy.ac.in") -> gayathiri.se23@bitsathy.ac.in | L9: =IFERROR(__xludf.DUMMYFUNCTION("XLOOKUP(B9, IMPORTRANGE(""https://docs.google.com/spreadsheets/d/1GpX_8hJc54hBz8KrakqcWdiXAS6pjY1zWE_9fWBXnEM/edit?gid=1460649486#gid=1460649486"", ""List!B:B""), IMPORTRANGE(""https://docs.google.com/spreadsheets/d/1GpX_8hJc54hBz8KrakqcWdiXAS6pjY1zWE_9fW"&"BXnEM/edit?gid=1460649486#gid=1460649486"", ""List!G:G""), ""-"")"),"6382761041") -> 6382761041 | M9: T&P | N9: 24.01.2026 | R9: YES
A10: 9 | B10: 7376231EC158 | C10: =IFERROR(__xludf.DUMMYFUNCTION("XLOOKUP(B10, IMPORTRANGE(""https://docs.google.com/spreadsheets/d/1UUC6R1hVFPCYDEbJMIXaIBW-jeQYiKTRixeKD_tUHGw/edit?gid=0#gid=0"", ""List!B:B""), IMPORTRANGE(""https://docs.google.com/spreadsheets/d/1UUC6R1hVFPCYDEbJMIXaIBW-jeQYiKTRixeKD_tUHGw/edit?gid=0#"&"gid=0"", ""List!C:C""), ""-"")"),"HARISHMITHA R") -> HARISHMITHA R | D10: =IFERROR(__xludf.DUMMYFUNCTION("XLOOKUP(B10, IMPORTRANGE(""https://docs.google.com/spreadsheets/d/1UUC6R1hVFPCYDEbJMIXaIBW-jeQYiKTRixeKD_tUHGw/edit?gid=0#gid=0"", ""List!B:B""), IMPORTRANGE(""https://docs.google.com/spreadsheets/d/1UUC6R1hVFPCYDEbJMIXaIBW-jeQYiKTRixeKD_tUHGw/edit?gid=0#"&"gid=0"", ""List!D:D""), ""-"")"),"ELECTRONICS AND COMMUNICATION ENGINEERING") -> ELECTRONICS AND COMMUNICATION ENGINEERING | E10: Soliton | F10: 10 | G10: Joined | H10: Online | I10: CORE | J10: Allow for Double the package | K10: =IFERROR(__xludf.DUMMYFUNCTION("XLOOKUP(B10, IMPORTRANGE(""https://docs.google.com/spreadsheets/d/1GpX_8hJc54hBz8KrakqcWdiXAS6pjY1zWE_9fWBXnEM/edit?gid=1460649486#gid=1460649486"", ""List!B:B""), IMPORTRANGE(""https://docs.google.com/spreadsheets/d/1GpX_8hJc54hBz8KrakqcWdiXAS6pjY1zWE_9f"&"WBXnEM/edit?gid=1460649486#gid=1460649486"", ""List!E:E""), ""-"")"),"harishmitha.ec23@bitsathy.ac.in") -> harishmitha.ec23@bitsathy.ac.in | L10: =IFERROR(__xludf.DUMMYFUNCTION("XLOOKUP(B10, IMPORTRANGE(""https://docs.google.com/spreadsheets/d/1GpX_8hJc54hBz8KrakqcWdiXAS6pjY1zWE_9fWBXnEM/edit?gid=1460649486#gid=1460649486"", ""List!B:B""), IMPORTRANGE(""https://docs.google.com/spreadsheets/d/1GpX_8hJc54hBz8KrakqcWdiXAS6pjY1zWE_9f"&"WBXnEM/edit?gid=1460649486#gid=1460649486"", ""List!G:G""), ""-"")"),"9345877323") -> 9345877323 | M10: T&P | N10: 24.01.2026 | R10: YES
A11: 10 | B11: 7376231EC140 | C11: =IFERROR(__xludf.DUMMYFUNCTION("XLOOKUP(B11, IMPORTRANGE(""https://docs.google.com/spreadsheets/d/1UUC6R1hVFPCYDEbJMIXaIBW-jeQYiKTRixeKD_tUHGw/edit?gid=0#gid=0"", ""List!B:B""), IMPORTRANGE(""https://docs.google.com/spreadsheets/d/1UUC6R1hVFPCYDEbJMIXaIBW-jeQYiKTRixeKD_tUHGw/edit?gid=0#"&"gid=0"", ""List!C:C""), ""-"")"),"DINESH S") -> DINESH S | D11: =IFERROR(__xludf.DUMMYFUNCTION("XLOOKUP(B11, IMPORTRANGE(""https://docs.google.com/spreadsheets/d/1UUC6R1hVFPCYDEbJMIXaIBW-jeQYiKTRixeKD_tUHGw/edit?gid=0#gid=0"", ""List!B:B""), IMPORTRANGE(""https://docs.google.com/spreadsheets/d/1UUC6R1hVFPCYDEbJMIXaIBW-jeQYiKTRixeKD_tUHGw/edit?gid=0#"&"gid=0"", ""List!D:D""), ""-"")"),"ELECTRONICS AND COMMUNICATION ENGINEERING") -> ELECTRONICS AND COMMUNICATION ENGINEERING | E11: Soliton | F11: 10 | G11: Joined | H11: Online | I11: CORE | J11: Allow for Double the package | K11: =IFERROR(__xludf.DUMMYFUNCTION("XLOOKUP(B11, IMPORTRANGE(""https://docs.google.com/spreadsheets/d/1GpX_8hJc54hBz8KrakqcWdiXAS6pjY1zWE_9fWBXnEM/edit?gid=1460649486#gid=1460649486"", ""List!B:B""), IMPORTRANGE(""https://docs.google.com/spreadsheets/d/1GpX_8hJc54hBz8KrakqcWdiXAS6pjY1zWE_9f"&"WBXnEM/edit?gid=1460649486#gid=1460649486"", ""List!E:E""), ""-"")"),"dinesh.ec23@bitsathy.ac.in") -> dinesh.ec23@bitsathy.ac.in | L11: =IFERROR(__xludf.DUMMYFUNCTION("XLOOKUP(B11, IMPORTRANGE(""https://docs.google.com/spreadsheets/d/1GpX_8hJc54hBz8KrakqcWdiXAS6pjY1zWE_9fWBXnEM/edit?gid=1460649486#gid=1460649486"", ""List!B:B""), IMPORTRANGE(""https://docs.google.com/spreadsheets/d/1GpX_8hJc54hBz8KrakqcWdiXAS6pjY1zWE_9f"&"WBXnEM/edit?gid=1460649486#gid=1460649486"", ""List!G:G""), ""-"")"),"8838289988") -> 8838289988 | M11: T&P | N11: 24.01.2026 | R11: YES
A12: 11 | B12: 7376231CS107 | C12: =IFERROR(__xludf.DUMMYFUNCTION("XLOOKUP(B12, IMPORTRANGE(""https://docs.google.com/spreadsheets/d/1UUC6R1hVFPCYDEbJMIXaIBW-jeQYiKTRixeKD_tUHGw/edit?gid=0#gid=0"", ""List!B:B""), IMPORTRANGE(""https://docs.google.com/spreadsheets/d/1UUC6R1hVFPCYDEbJMIXaIBW-jeQYiKTRixeKD_tUHGw/edit?gid=0#"&"gid=0"", ""List!C:C""), ""-"")"),"ADHAVAN SE V") -> ADHAVAN SE V | D12: =IFERROR(__xludf.DUMMYFUNCTION("XLOOKUP(B12, IMPORTRANGE(""https://docs.google.com/spreadsheets/d/1UUC6R1hVFPCYDEbJMIXaIBW-jeQYiKTRixeKD_tUHGw/edit?gid=0#gid=0"", ""List!B:B""), IMPORTRANGE(""https://docs.google.com/spreadsheets/d/1UUC6R1hVFPCYDEbJMIXaIBW-jeQYiKTRixeKD_tUHGw/edit?gid=0#"&"gid=0"", ""List!D:D""), ""-"")"),"COMPUTER SCIENCE AND ENGINEERING") -> COMPUTER SCIENCE AND ENGINEERING | E12: Soliton | F12: 10 | G12: Joined | H12: Online | I12: CORE | J12: Dont Allow | K12: =IFERROR(__xludf.DUMMYFUNCTION("XLOOKUP(B12, IMPORTRANGE(""https://docs.google.com/spreadsheets/d/1GpX_8hJc54hBz8KrakqcWdiXAS6pjY1zWE_9fWBXnEM/edit?gid=1460649486#gid=1460649486"", ""List!B:B""), IMPORTRANGE(""https://docs.google.com/spreadsheets/d/1GpX_8hJc54hBz8KrakqcWdiXAS6pjY1zWE_9f"&"WBXnEM/edit?gid=1460649486#gid=1460649486"", ""List!E:E""), ""-"")"),"adhavan.cs23@bitsathy.ac.in") -> adhavan.cs23@bitsathy.ac.in | L12: =IFERROR(__xludf.DUMMYFUNCTION("XLOOKUP(B12, IMPORTRANGE(""https://docs.google.com/spreadsheets/d/1GpX_8hJc54hBz8KrakqcWdiXAS6pjY1zWE_9fWBXnEM/edit?gid=1460649486#gid=1460649486"", ""List!B:B""), IMPORTRANGE(""https://docs.google.com/spreadsheets/d/1GpX_8hJc54hBz8KrakqcWdiXAS6pjY1zWE_9f"&"WBXnEM/edit?gid=1460649486#gid=1460649486"", ""List!G:G""), ""-"")"),"9486406279") -> 9486406279 | M12: T&P | N12: 24.01.2026 | R12: YES
A13: 12 | B13: 7376232AD252 | C13: =IFERROR(__xludf.DUMMYFUNCTION("XLOOKUP(B13, IMPORTRANGE(""https://docs.google.com/spreadsheets/d/1UUC6R1hVFPCYDEbJMIXaIBW-jeQYiKTRixeKD_tUHGw/edit?gid=0#gid=0"", ""List!B:B""), IMPORTRANGE(""https://docs.google.com/spreadsheets/d/1UUC6R1hVFPCYDEbJMIXaIBW-jeQYiKTRixeKD_tUHGw/edit?gid=0#"&"gid=0"", ""List!C:C""), ""-"")"),"SHARVESH RAMALINGAM") -> SHARVESH RAMALINGAM | D13: =IFERROR(__xludf.DUMMYFUNCTION("XLOOKUP(B13, IMPORTRANGE(""https://docs.google.com/spreadsheets/d/1UUC6R1hVFPCYDEbJMIXaIBW-jeQYiKTRixeKD_tUHGw/edit?gid=0#gid=0"", ""List!B:B""), IMPORTRANGE(""https://docs.google.com/spreadsheets/d/1UUC6R1hVFPCYDEbJMIXaIBW-jeQYiKTRixeKD_tUHGw/edit?gid=0#"&"gid=0"", ""List!D:D""), ""-"")"),"ARTIFICIAL INTELLIGENCE AND DATA SCIENCE") -> ARTIFICIAL INTELLIGENCE AND DATA SCIENCE | E13: Soliton | F13: 10 | G13: Joined | H13: Online | I13: CORE | J13: Allow for Double the package | K13: =IFERROR(__xludf.DUMMYFUNCTION("XLOOKUP(B13, IMPORTRANGE(""https://docs.google.com/spreadsheets/d/1GpX_8hJc54hBz8KrakqcWdiXAS6pjY1zWE_9fWBXnEM/edit?gid=1460649486#gid=1460649486"", ""List!B:B""), IMPORTRANGE(""https://docs.google.com/spreadsheets/d/1GpX_8hJc54hBz8KrakqcWdiXAS6pjY1zWE_9f"&"WBXnEM/edit?gid=1460649486#gid=1460649486"", ""List!E:E""), ""-"")"),"sharvesh.ad23@bitsathy.ac.in") -> sharvesh.ad23@bitsathy.ac.in | L13: =IFERROR(__xludf.DUMMYFUNCTION("XLOOKUP(B13, IMPORTRANGE(""https://docs.google.com/spreadsheets/d/1GpX_8hJc54hBz8KrakqcWdiXAS6pjY1zWE_9fWBXnEM/edit?gid=1460649486#gid=1460649486"", ""List!B:B""), IMPORTRANGE(""https://docs.google.com/spreadsheets/d/1GpX_8hJc54hBz8KrakqcWdiXAS6pjY1zWE_9f"&"WBXnEM/edit?gid=1460649486#gid=1460649486"", ""List!G:G""), ""-"")"),"9944872008") -> 9944872008 | M13: T&P | N13: 24.01.2026 | R13: YES
A14: 13 | B14: 7376232AD195 | C14: =IFERROR(__xludf.DUMMYFUNCTION("XLOOKUP(B14, IMPORTRANGE(""https://docs.google.com/spreadsheets/d/1UUC6R1hVFPCYDEbJMIXaIBW-jeQYiKTRixeKD_tUHGw/edit?gid=0#gid=0"", ""List!B:B""), IMPORTRANGE(""https://docs.google.com/spreadsheets/d/1UUC6R1hVFPCYDEbJMIXaIBW-jeQYiKTRixeKD_tUHGw/edit?gid=0#"&"gid=0"", ""List!C:C""), ""-"")"),"MOHAMMED AFEEF M") -> MOHAMMED AFEEF M | D14: =IFERROR(__xludf.DUMMYFUNCTION("XLOOKUP(B14, IMPORTRANGE(""https://docs.google.com/spreadsheets/d/1UUC6R1hVFPCYDEbJMIXaIBW-jeQYiKTRixeKD_tUHGw/edit?gid=0#gid=0"", ""List!B:B""), IMPORTRANGE(""https://docs.google.com/spreadsheets/d/1UUC6R1hVFPCYDEbJMIXaIBW-jeQYiKTRixeKD_tUHGw/edit?gid=0#"&"gid=0"", ""List!D:D""), ""-"")"),"ARTIFICIAL INTELLIGENCE AND DATA SCIENCE") -> ARTIFICIAL INTELLIGENCE AND DATA SCIENCE | E14: Soliton | F14: 10 | G14: Joined | H14: Online | I14: CORE | J14: Allow for Double the package | K14: =IFERROR(__xludf.DUMMYFUNCTION("XLOOKUP(B14, IMPORTRANGE(""https://docs.google.com/spreadsheets/d/1GpX_8hJc54hBz8KrakqcWdiXAS6pjY1zWE_9fWBXnEM/edit?gid=1460649486#gid=1460649486"", ""List!B:B""), IMPORTRANGE(""https://docs.google.com/spreadsheets/d/1GpX_8hJc54hBz8KrakqcWdiXAS6pjY1zWE_9f"&"WBXnEM/edit?gid=1460649486#gid=1460649486"", ""List!E:E""), ""-"")"),"mohammedafeef.ad23@bitsathy.ac.in") -> mohammedafeef.ad23@bitsathy.ac.in | L14: =IFERROR(__xludf.DUMMYFUNCTION("XLOOKUP(B14, IMPORTRANGE(""https://docs.google.com/spreadsheets/d/1GpX_8hJc54hBz8KrakqcWdiXAS6pjY1zWE_9fWBXnEM/edit?gid=1460649486#gid=1460649486"", ""List!B:B""), IMPORTRANGE(""https://docs.google.com/spreadsheets/d/1GpX_8hJc54hBz8KrakqcWdiXAS6pjY1zWE_9f"&"WBXnEM/edit?gid=1460649486#gid=1460649486"", ""List!G:G""), ""-"")"),"7339424994") -> 7339424994 | M14: T&P | N14: 24.01.2026 | R14: YES
A15: 14 | B15: 7376231EC192 | C15: =IFERROR(__xludf.DUMMYFUNCTION("XLOOKUP(B15, IMPORTRANGE(""https://docs.google.com/spreadsheets/d/1UUC6R1hVFPCYDEbJMIXaIBW-jeQYiKTRixeKD_tUHGw/edit?gid=0#gid=0"", ""List!B:B""), IMPORTRANGE(""https://docs.google.com/spreadsheets/d/1UUC6R1hVFPCYDEbJMIXaIBW-jeQYiKTRixeKD_tUHGw/edit?gid=0#"&"gid=0"", ""List!C:C""), ""-"")"),"KOUSIK A B") -> KOUSIK A B | D15: =IFERROR(__xludf.DUMMYFUNCTION("XLOOKUP(B15, IMPORTRANGE(""https://docs.google.com/spreadsheets/d/1UUC6R1hVFPCYDEbJMIXaIBW-jeQYiKTRixeKD_tUHGw/edit?gid=0#gid=0"", ""List!B:B""), IMPORTRANGE(""https://docs.google.com/spreadsheets/d/1UUC6R1hVFPCYDEbJMIXaIBW-jeQYiKTRixeKD_tUHGw/edit?gid=0#"&"gid=0"", ""List!D:D""), ""-"")"),"ELECTRONICS AND COMMUNICATION ENGINEERING") -> ELECTRONICS AND COMMUNICATION ENGINEERING | E15: Soliton | F15: 10 | G15: Joined | H15: Online | I15: CORE | J15: Allow for Double the package | K15: =IFERROR(__xludf.DUMMYFUNCTION("XLOOKUP(B15, IMPORTRANGE(""https://docs.google.com/spreadsheets/d/1GpX_8hJc54hBz8KrakqcWdiXAS6pjY1zWE_9fWBXnEM/edit?gid=1460649486#gid=1460649486"", ""List!B:B""), IMPORTRANGE(""https://docs.google.com/spreadsheets/d/1GpX_8hJc54hBz8KrakqcWdiXAS6pjY1zWE_9f"&"WBXnEM/edit?gid=1460649486#gid=1460649486"", ""List!E:E""), ""-"")"),"kousik.ec23@bitsathy.ac.in") -> kousik.ec23@bitsathy.ac.in | L15: =IFERROR(__xludf.DUMMYFUNCTION("XLOOKUP(B15, IMPORTRANGE(""https://docs.google.com/spreadsheets/d/1GpX_8hJc54hBz8KrakqcWdiXAS6pjY1zWE_9fWBXnEM/edit?gid=1460649486#gid=1460649486"", ""List!B:B""), IMPORTRANGE(""https://docs.google.com/spreadsheets/d/1GpX_8hJc54hBz8KrakqcWdiXAS6pjY1zWE_9f"&"WBXnEM/edit?gid=1460649486#gid=1460649486"", ""List!G:G""), ""-"")"),"8190077771") -> 8190077771 | M15: T&P | N15: 24.01.2026 | R15: YES
A16: 15 | B16: 7376232AD101 | C16: =IFERROR(__xludf.DUMMYFUNCTION("XLOOKUP(B16, IMPORTRANGE(""https://docs.google.com/spreadsheets/d/1UUC6R1hVFPCYDEbJMIXaIBW-jeQYiKTRixeKD_tUHGw/edit?gid=0#gid=0"", ""List!B:B""), IMPORTRANGE(""https://docs.google.com/spreadsheets/d/1UUC6R1hVFPCYDEbJMIXaIBW-jeQYiKTRixeKD_tUHGw/edit?gid=0#"&"gid=0"", ""List!C:C""), ""-"")"),"AATHINI S S") -> AATHINI S S | D16: =IFERROR(__xludf.DUMMYFUNCTION("XLOOKUP(B16, IMPORTRANGE(""https://docs.google.com/spreadsheets/d/1UUC6R1hVFPCYDEbJMIXaIBW-jeQYiKTRixeKD_tUHGw/edit?gid=0#gid=0"", ""List!B:B""), IMPORTRANGE(""https://docs.google.com/spreadsheets/d/1UUC6R1hVFPCYDEbJMIXaIBW-jeQYiKTRixeKD_tUHGw/edit?gid=0#"&"gid=0"", ""List!D:D""), ""-"")"),"ARTIFICIAL INTELLIGENCE AND DATA SCIENCE") -> ARTIFICIAL INTELLIGENCE AND DATA SCIENCE | E16: Workhall | F16: 5 | G16: Joined | H16: Offline | I16: ITP | J16: Allow for Double the package | K16: =IFERROR(__xludf.DUMMYFUNCTION("XLOOKUP(B16, IMPORTRANGE(""https://docs.google.com/spreadsheets/d/1GpX_8hJc54hBz8KrakqcWdiXAS6pjY1zWE_9fWBXnEM/edit?gid=1460649486#gid=1460649486"", ""List!B:B""), IMPORTRANGE(""https://docs.google.com/spreadsheets/d/1GpX_8hJc54hBz8KrakqcWdiXAS6pjY1zWE_9f"&"WBXnEM/edit?gid=1460649486#gid=1460649486"", ""List!E:E""), ""-"")"),"aathini.ad23@bitsathy.ac.in") -> aathini.ad23@bitsathy.ac.in | L16: =IFERROR(__xludf.DUMMYFUNCTION("XLOOKUP(B16, IMPORTRANGE(""https://docs.google.com/spreadsheets/d/1GpX_8hJc54hBz8KrakqcWdiXAS6pjY1zWE_9fWBXnEM/edit?gid=1460649486#gid=1460649486"", ""List!B:B""), IMPORTRANGE(""https://docs.google.com/spreadsheets/d/1GpX_8hJc54hBz8KrakqcWdiXAS6pjY1zWE_9f"&"WBXnEM/edit?gid=1460649486#gid=1460649486"", ""List!G:G""), ""-"")"),"9345795447") -> 9345795447 | M16: T&P | N16: 07.02.2026 | O16: 09.02.2026 | R16: YES
A17: 16 | B17: 7376232AD169 | C17: =IFERROR(__xludf.DUMMYFUNCTION("XLOOKUP(B17, IMPORTRANGE(""https://docs.google.com/spreadsheets/d/1UUC6R1hVFPCYDEbJMIXaIBW-jeQYiKTRixeKD_tUHGw/edit?gid=0#gid=0"", ""List!B:B""), IMPORTRANGE(""https://docs.google.com/spreadsheets/d/1UUC6R1hVFPCYDEbJMIXaIBW-jeQYiKTRixeKD_tUHGw/edit?gid=0#"&"gid=0"", ""List!C:C""), ""-"")"),"JOGITHA R S") -> JOGITHA R S | D17: =IFERROR(__xludf.DUMMYFUNCTION("XLOOKUP(B17, IMPORTRANGE(""https://docs.google.com/spreadsheets/d/1UUC6R1hVFPCYDEbJMIXaIBW-jeQYiKTRixeKD_tUHGw/edit?gid=0#gid=0"", ""List!B:B""), IMPORTRANGE(""https://docs.google.com/spreadsheets/d/1UUC6R1hVFPCYDEbJMIXaIBW-jeQYiKTRixeKD_tUHGw/edit?gid=0#"&"gid=0"", ""List!D:D""), ""-"")"),"ARTIFICIAL INTELLIGENCE AND DATA SCIENCE") -> ARTIFICIAL INTELLIGENCE AND DATA SCIENCE | E17: Workhall | F17: 5 | G17: Joined | H17: Offline | I17: ITP | J17: Allow for Double the package | K17: =IFERROR(__xludf.DUMMYFUNCTION("XLOOKUP(B17, IMPORTRANGE(""https://docs.google.com/spreadsheets/d/1GpX_8hJc54hBz8KrakqcWdiXAS6pjY1zWE_9fWBXnEM/edit?gid=1460649486#gid=1460649486"", ""List!B:B""), IMPORTRANGE(""https://docs.google.com/spreadsheets/d/1GpX_8hJc54hBz8KrakqcWdiXAS6pjY1zWE_9f"&"WBXnEM/edit?gid=1460649486#gid=1460649486"", ""List!E:E""), ""-"")"),"jogitha.ad23@bitsathy.ac.in") -> jogitha.ad23@bitsathy.ac.in | L17: =IFERROR(__xludf.DUMMYFUNCTION("XLOOKUP(B17, IMPORTRANGE(""https://docs.google.com/spreadsheets/d/1GpX_8hJc54hBz8KrakqcWdiXAS6pjY1zWE_9fWBXnEM/edit?gid=1460649486#gid=1460649486"", ""List!B:B""), IMPORTRANGE(""https://docs.google.com/spreadsheets/d/1GpX_8hJc54hBz8KrakqcWdiXAS6pjY1zWE_9f"&"WBXnEM/edit?gid=1460649486#gid=1460649486"", ""List!G:G""), ""-"")"),"6382440479") -> 6382440479 | M17: T&P | N17: 07.02.2026 | O17: 09.02.2026 | R17: YES
A18: 17 | B18: 7376232AL112 | C18: =IFERROR(__xludf.DUMMYFUNCTION("XLOOKUP(B18, IMPORTRANGE(""https://docs.google.com/spreadsheets/d/1UUC6R1hVFPCYDEbJMIXaIBW-jeQYiKTRixeKD_tUHGw/edit?gid=0#gid=0"", ""List!B:B""), IMPORTRANGE(""https://docs.google.com/spreadsheets/d/1UUC6R1hVFPCYDEbJMIXaIBW-jeQYiKTRixeKD_tUHGw/edit?gid=0#"&"gid=0"", ""List!C:C""), ""-"")"),"DEEKSHA M M") -> DEEKSHA M M | D18: =IFERROR(__xludf.DUMMYFUNCTION("XLOOKUP(B18, IMPORTRANGE(""https://docs.google.com/spreadsheets/d/1UUC6R1hVFPCYDEbJMIXaIBW-jeQYiKTRixeKD_tUHGw/edit?gid=0#gid=0"", ""List!B:B""), IMPORTRANGE(""https://docs.google.com/spreadsheets/d/1UUC6R1hVFPCYDEbJMIXaIBW-jeQYiKTRixeKD_tUHGw/edit?gid=0#"&"gid=0"", ""List!D:D""), ""-"")"),"ARTIFICIAL INTELLIGENCE AND MACHINE LEARNING") -> ARTIFICIAL INTELLIGENCE AND MACHINE LEARNING | E18: Workhall | F18: 5 | G18: Joined | H18: Offline | I18: ITP | J18: Allow for Double the package | K18: =IFERROR(__xludf.DUMMYFUNCTION("XLOOKUP(B18, IMPORTRANGE(""https://docs.google.com/spreadsheets/d/1GpX_8hJc54hBz8KrakqcWdiXAS6pjY1zWE_9fWBXnEM/edit?gid=1460649486#gid=1460649486"", ""List!B:B""), IMPORTRANGE(""https://docs.google.com/spreadsheets/d/1GpX_8hJc54hBz8KrakqcWdiXAS6pjY1zWE_9f"&"WBXnEM/edit?gid=1460649486#gid=1460649486"", ""List!E:E""), ""-"")"),"deeksha.al23@bitsathy.ac.in") -> deeksha.al23@bitsathy.ac.in | L18: =IFERROR(__xludf.DUMMYFUNCTION("XLOOKUP(B18, IMPORTRANGE(""https://docs.google.com/spreadsheets/d/1GpX_8hJc54hBz8KrakqcWdiXAS6pjY1zWE_9fWBXnEM/edit?gid=1460649486#gid=1460649486"", ""List!B:B""), IMPORTRANGE(""https://docs.google.com/spreadsheets/d/1GpX_8hJc54hBz8KrakqcWdiXAS6pjY1zWE_9f"&"WBXnEM/edit?gid=1460649486#gid=1460649486"", ""List!G:G""), ""-"")"),"6374950166") -> 6374950166 | M18: T&P | N18: 07.02.2026 | O18: 09.02.2026 | R18: YES
A19: 18 | B19: 7376232AL139 | C19: =IFERROR(__xludf.DUMMYFUNCTION("XLOOKUP(B19, IMPORTRANGE(""https://docs.google.com/spreadsheets/d/1UUC6R1hVFPCYDEbJMIXaIBW-jeQYiKTRixeKD_tUHGw/edit?gid=0#gid=0"", ""List!B:B""), IMPORTRANGE(""https://docs.google.com/spreadsheets/d/1UUC6R1hVFPCYDEbJMIXaIBW-jeQYiKTRixeKD_tUHGw/edit?gid=0#"&"gid=0"", ""List!C:C""), ""-"")"),"KIRANYA S R") -> KIRANYA S R | D19: =IFERROR(__xludf.DUMMYFUNCTION("XLOOKUP(B19, IMPORTRANGE(""https://docs.google.com/spreadsheets/d/1UUC6R1hVFPCYDEbJMIXaIBW-jeQYiKTRixeKD_tUHGw/edit?gid=0#gid=0"", ""List!B:B""), IMPORTRANGE(""https://docs.google.com/spreadsheets/d/1UUC6R1hVFPCYDEbJMIXaIBW-jeQYiKTRixeKD_tUHGw/edit?gid=0#"&"gid=0"", ""List!D:D""), ""-"")"),"ARTIFICIAL INTELLIGENCE AND MACHINE LEARNING") -> ARTIFICIAL INTELLIGENCE AND MACHINE LEARNING | E19: Workhall | F19: 5 | G19: Joined | H19: Offline | I19: ITP | J19: Allow for Double the package | K19: =IFERROR(__xludf.DUMMYFUNCTION("XLOOKUP(B19, IMPORTRANGE(""https://docs.google.com/spreadsheets/d/1GpX_8hJc54hBz8KrakqcWdiXAS6pjY1zWE_9fWBXnEM/edit?gid=1460649486#gid=1460649486"", ""List!B:B""), IMPORTRANGE(""https://docs.google.com/spreadsheets/d/1GpX_8hJc54hBz8KrakqcWdiXAS6pjY1zWE_9f"&"WBXnEM/edit?gid=1460649486#gid=1460649486"", ""List!E:E""), ""-"")"),"kiranya.al23@bitsathy.ac.in") -> kiranya.al23@bitsathy.ac.in | L19: =IFERROR(__xludf.DUMMYFUNCTION("XLOOKUP(B19, IMPORTRANGE(""https://docs.google.com/spreadsheets/d/1GpX_8hJc54hBz8KrakqcWdiXAS6pjY1zWE_9fWBXnEM/edit?gid=1460649486#gid=1460649486"", ""List!B:B""), IMPORTRANGE(""https://docs.google.com/spreadsheets/d/1GpX_8hJc54hBz8KrakqcWdiXAS6pjY1zWE_9f"&"WBXnEM/edit?gid=1460649486#gid=1460649486"", ""List!G:G""), ""-"")"),"9043405454") -> 9043405454 | M19: T&P | N19: 07.02.2026 | O19: 09.02.2026 | R19: YES
A20: 19 | B20: 7376232AL151 | C20: =IFERROR(__xludf.DUMMYFUNCTION("XLOOKUP(B20, IMPORTRANGE(""https://docs.google.com/spreadsheets/d/1UUC6R1hVFPCYDEbJMIXaIBW-jeQYiKTRixeKD_tUHGw/edit?gid=0#gid=0"", ""List!B:B""), IMPORTRANGE(""https://docs.google.com/spreadsheets/d/1UUC6R1hVFPCYDEbJMIXaIBW-jeQYiKTRixeKD_tUHGw/edit?gid=0#"&"gid=0"", ""List!C:C""), ""-"")"),"MAHITHAA SRI S K") -> MAHITHAA SRI S K | D20: =IFERROR(__xludf.DUMMYFUNCTION("XLOOKUP(B20, IMPORTRANGE(""https://docs.google.com/spreadsheets/d/1UUC6R1hVFPCYDEbJMIXaIBW-jeQYiKTRixeKD_tUHGw/edit?gid=0#gid=0"", ""List!B:B""), IMPORTRANGE(""https://docs.google.com/spreadsheets/d/1UUC6R1hVFPCYDEbJMIXaIBW-jeQYiKTRixeKD_tUHGw/edit?gid=0#"&"gid=0"", ""List!D:D""), ""-"")"),"ARTIFICIAL INTELLIGENCE AND MACHINE LEARNING") -> ARTIFICIAL INTELLIGENCE AND MACHINE LEARNING | E20: Workhall | F20: 5 | G20: Joined | H20: Offline | I20: ITP | J20: Allow for Double the package | K20: =IFERROR(__xludf.DUMMYFUNCTION("XLOOKUP(B20, IMPORTRANGE(""https://docs.google.com/spreadsheets/d/1GpX_8hJc54hBz8KrakqcWdiXAS6pjY1zWE_9fWBXnEM/edit?gid=1460649486#gid=1460649486"", ""List!B:B""), IMPORTRANGE(""https://docs.google.com/spreadsheets/d/1GpX_8hJc54hBz8KrakqcWdiXAS6pjY1zWE_9f"&"WBXnEM/edit?gid=1460649486#gid=1460649486"", ""List!E:E""), ""-"")"),"mahithaasri.al23@bitsathy.ac.in") -> mahithaasri.al23@bitsathy.ac.in | L20: =IFERROR(__xludf.DUMMYFUNCTION("XLOOKUP(B20, IMPORTRANGE(""https://docs.google.com/spreadsheets/d/1GpX_8hJc54hBz8KrakqcWdiXAS6pjY1zWE_9fWBXnEM/edit?gid=1460649486#gid=1460649486"", ""List!B:B""), IMPORTRANGE(""https://docs.google.com/spreadsheets/d/1GpX_8hJc54hBz8KrakqcWdiXAS6pjY1zWE_9f"&"WBXnEM/edit?gid=1460649486#gid=1460649486"", ""List!G:G""), ""-"")"),"9444505595") -> 9444505595 | M20: T&P | N20: 07.02.2026 | O20: 09.02.2026 | R20: YES
A21: 20 | B21: 7376232AL170 | C21: =IFERROR(__xludf.DUMMYFUNCTION("XLOOKUP(B21, IMPORTRANGE(""https://docs.google.com/spreadsheets/d/1UUC6R1hVFPCYDEbJMIXaIBW-jeQYiKTRixeKD_tUHGw/edit?gid=0#gid=0"", ""List!B:B""), IMPORTRANGE(""https://docs.google.com/spreadsheets/d/1UUC6R1hVFPCYDEbJMIXaIBW-jeQYiKTRixeKD_tUHGw/edit?gid=0#"&"gid=0"", ""List!C:C""), ""-"")"),"NIDHARSANA K S") -> NIDHARSANA K S | D21: =IFERROR(__xludf.DUMMYFUNCTION("XLOOKUP(B21, IMPORTRANGE(""https://docs.google.com/spreadsheets/d/1UUC6R1hVFPCYDEbJMIXaIBW-jeQYiKTRixeKD_tUHGw/edit?gid=0#gid=0"", ""List!B:B""), IMPORTRANGE(""https://docs.google.com/spreadsheets/d/1UUC6R1hVFPCYDEbJMIXaIBW-jeQYiKTRixeKD_tUHGw/edit?gid=0#"&"gid=0"", ""List!D:D""), ""-"")"),"ARTIFICIAL INTELLIGENCE AND MACHINE LEARNING") -> ARTIFICIAL INTELLIGENCE AND MACHINE LEARNING | E21: Workhall | F21: 5 | G21: Joined | H21: Offline | I21: ITP | J21: Allow for Double the package | K21: =IFERROR(__xludf.DUMMYFUNCTION("XLOOKUP(B21, IMPORTRANGE(""https://docs.google.com/spreadsheets/d/1GpX_8hJc54hBz8KrakqcWdiXAS6pjY1zWE_9fWBXnEM/edit?gid=1460649486#gid=1460649486"", ""List!B:B""), IMPORTRANGE(""https://docs.google.com/spreadsheets/d/1GpX_8hJc54hBz8KrakqcWdiXAS6pjY1zWE_9f"&"WBXnEM/edit?gid=1460649486#gid=1460649486"", ""List!E:E""), ""-"")"),"nidharsana.al23@bitsathy.ac.in") -> nidharsana.al23@bitsathy.ac.in | L21: =IFERROR(__xludf.DUMMYFUNCTION("XLOOKUP(B21, IMPORTRANGE(""https://docs.google.com/spreadsheets/d/1GpX_8hJc54hBz8KrakqcWdiXAS6pjY1zWE_9fWBXnEM/edit?gid=1460649486#gid=1460649486"", ""List!B:B""), IMPORTRANGE(""https://docs.google.com/spreadsheets/d/1GpX_8hJc54hBz8KrakqcWdiXAS6pjY1zWE_9f"&"WBXnEM/edit?gid=1460649486#gid=1460649486"", ""List!G:G""), ""-"")"),"8122744801") -> 8122744801 | M21: T&P | N21: 07.02.2026 | O21: 09.02.2026 | R21: YES
A22: 21 | B22: 7376232CB118 | C22: =IFERROR(__xludf.DUMMYFUNCTION("XLOOKUP(B22, IMPORTRANGE(""https://docs.google.com/spreadsheets/d/1UUC6R1hVFPCYDEbJMIXaIBW-jeQYiKTRixeKD_tUHGw/edit?gid=0#gid=0"", ""List!B:B""), IMPORTRANGE(""https://docs.google.com/spreadsheets/d/1UUC6R1hVFPCYDEbJMIXaIBW-jeQYiKTRixeKD_tUHGw/edit?gid=0#"&"gid=0"", ""List!C:C""), ""-"")"),"GOWRI SHANKAR P") -> GOWRI SHANKAR P | D22: =IFERROR(__xludf.DUMMYFUNCTION("XLOOKUP(B22, IMPORTRANGE(""https://docs.google.com/spreadsheets/d/1UUC6R1hVFPCYDEbJMIXaIBW-jeQYiKTRixeKD_tUHGw/edit?gid=0#gid=0"", ""List!B:B""), IMPORTRANGE(""https://docs.google.com/spreadsheets/d/1UUC6R1hVFPCYDEbJMIXaIBW-jeQYiKTRixeKD_tUHGw/edit?gid=0#"&"gid=0"", ""List!D:D""), ""-"")"),"COMPUTER SCIENCE AND BUSINESS SYSTEMS") -> COMPUTER SCIENCE AND BUSINESS SYSTEMS | E22: Workhall | F22: 5 | G22: Joined | H22: Offline | I22: ITP | J22: Allow for Double the package | K22: =IFERROR(__xludf.DUMMYFUNCTION("XLOOKUP(B22, IMPORTRANGE(""https://docs.google.com/spreadsheets/d/1GpX_8hJc54hBz8KrakqcWdiXAS6pjY1zWE_9fWBXnEM/edit?gid=1460649486#gid=1460649486"", ""List!B:B""), IMPORTRANGE(""https://docs.google.com/spreadsheets/d/1GpX_8hJc54hBz8KrakqcWdiXAS6pjY1zWE_9f"&"WBXnEM/edit?gid=1460649486#gid=1460649486"", ""List!E:E""), ""-"")"),"gowrishankar.cb23@bitsathy.ac.in") -> gowrishankar.cb23@bitsathy.ac.in | L22: =IFERROR(__xludf.DUMMYFUNCTION("XLOOKUP(B22, IMPORTRANGE(""https://docs.google.com/spreadsheets/d/1GpX_8hJc54hBz8KrakqcWdiXAS6pjY1zWE_9fWBXnEM/edit?gid=1460649486#gid=1460649486"", ""List!B:B""), IMPORTRANGE(""https://docs.google.com/spreadsheets/d/1GpX_8hJc54hBz8KrakqcWdiXAS6pjY1zWE_9f"&"WBXnEM/edit?gid=1460649486#gid=1460649486"", ""List!G:G""), ""-"")"),"6383869580") -> 6383869580 | M22: T&P | N22: 07.02.2026 | O22: 09.02.2026 | R22: YES
A23: 22 | B23: 7376232IT272 | C23: =IFERROR(__xludf.DUMMYFUNCTION("XLOOKUP(B23, IMPORTRANGE(""https://docs.google.com/spreadsheets/d/1UUC6R1hVFPCYDEbJMIXaIBW-jeQYiKTRixeKD_tUHGw/edit?gid=0#gid=0"", ""List!B:B""), IMPORTRANGE(""https://docs.google.com/spreadsheets/d/1UUC6R1hVFPCYDEbJMIXaIBW-jeQYiKTRixeKD_tUHGw/edit?gid=0#"&"gid=0"", ""List!C:C""), ""-"")"),"THITHIKSAA S K") -> THITHIKSAA S K | D23: =IFERROR(__xludf.DUMMYFUNCTION("XLOOKUP(B23, IMPORTRANGE(""https://docs.google.com/spreadsheets/d/1UUC6R1hVFPCYDEbJMIXaIBW-jeQYiKTRixeKD_tUHGw/edit?gid=0#gid=0"", ""List!B:B""), IMPORTRANGE(""https://docs.google.com/spreadsheets/d/1UUC6R1hVFPCYDEbJMIXaIBW-jeQYiKTRixeKD_tUHGw/edit?gid=0#"&"gid=0"", ""List!D:D""), ""-"")"),"INFORMATION TECHNOLOGY") -> INFORMATION TECHNOLOGY | E23: Workhall | F23: 5 | G23: Joined | H23: Offline | I23: ITP | J23: Allow for Double the package | K23: =IFERROR(__xludf.DUMMYFUNCTION("XLOOKUP(B23, IMPORTRANGE(""https://docs.google.com/spreadsheets/d/1GpX_8hJc54hBz8KrakqcWdiXAS6pjY1zWE_9fWBXnEM/edit?gid=1460649486#gid=1460649486"", ""List!B:B""), IMPORTRANGE(""https://docs.google.com/spreadsheets/d/1GpX_8hJc54hBz8KrakqcWdiXAS6pjY1zWE_9f"&"WBXnEM/edit?gid=1460649486#gid=1460649486"", ""List!E:E""), ""-"")"),"thithiksaa.it23@bitsathy.ac.in") -> thithiksaa.it23@bitsathy.ac.in | L23: =IFERROR(__xludf.DUMMYFUNCTION("XLOOKUP(B23, IMPORTRANGE(""https://docs.google.com/spreadsheets/d/1GpX_8hJc54hBz8KrakqcWdiXAS6pjY1zWE_9fWBXnEM/edit?gid=1460649486#gid=1460649486"", ""List!B:B""), IMPORTRANGE(""https://docs.google.com/spreadsheets/d/1GpX_8hJc54hBz8KrakqcWdiXAS6pjY1zWE_9f"&"WBXnEM/edit?gid=1460649486#gid=1460649486"", ""List!G:G""), ""-"")"),"9489431540") -> 9489431540 | M23: T&P | N23: 07.02.2026 | O23: 09.02.2026 | R23: YES
A24: 23 | B24: 7376231CS250 | C24: =IFERROR(__xludf.DUMMYFUNCTION("XLOOKUP(B24, IMPORTRANGE(""https://docs.google.com/spreadsheets/d/1UUC6R1hVFPCYDEbJMIXaIBW-jeQYiKTRixeKD_tUHGw/edit?gid=0#gid=0"", ""List!B:B""), IMPORTRANGE(""https://docs.google.com/spreadsheets/d/1UUC6R1hVFPCYDEbJMIXaIBW-jeQYiKTRixeKD_tUHGw/edit?gid=0#"&"gid=0"", ""List!C:C""), ""-"")"),"NITHIKAA M") -> NITHIKAA M | D24: =IFERROR(__xludf.DUMMYFUNCTION("XLOOKUP(B24, IMPORTRANGE(""https://docs.google.com/spreadsheets/d/1UUC6R1hVFPCYDEbJMIXaIBW-jeQYiKTRixeKD_tUHGw/edit?gid=0#gid=0"", ""List!B:B""), IMPORTRANGE(""https://docs.google.com/spreadsheets/d/1UUC6R1hVFPCYDEbJMIXaIBW-jeQYiKTRixeKD_tUHGw/edit?gid=0#"&"gid=0"", ""List!D:D""), ""-"")"),"COMPUTER SCIENCE AND ENGINEERING") -> COMPUTER SCIENCE AND ENGINEERING | E24: Workhall | F24: 5 | G24: Joined | H24: Offline | I24: ITP | J24: Allow for Double the package | K24: =IFERROR(__xludf.DUMMYFUNCTION("XLOOKUP(B24, IMPORTRANGE(""https://docs.google.com/spreadsheets/d/1GpX_8hJc54hBz8KrakqcWdiXAS6pjY1zWE_9fWBXnEM/edit?gid=1460649486#gid=1460649486"", ""List!B:B""), IMPORTRANGE(""https://docs.google.com/spreadsheets/d/1GpX_8hJc54hBz8KrakqcWdiXAS6pjY1zWE_9f"&"WBXnEM/edit?gid=1460649486#gid=1460649486"", ""List!E:E""), ""-"")"),"nithikaa.cs23@bitsathy.ac.in") -> nithikaa.cs23@bitsathy.ac.in | L24: =IFERROR(__xludf.DUMMYFUNCTION("XLOOKUP(B24, IMPORTRANGE(""https://docs.google.com/spreadsheets/d/1GpX_8hJc54hBz8KrakqcWdiXAS6pjY1zWE_9fWBXnEM/edit?gid=1460649486#gid=1460649486"", ""List!B:B""), IMPORTRANGE(""https://docs.google.com/spreadsheets/d/1GpX_8hJc54hBz8KrakqcWdiXAS6pjY1zWE_9f"&"WBXnEM/edit?gid=1460649486#gid=1460649486"", ""List!G:G""), ""-"")"),"9025623528") -> 9025623528 | M24: T&P | N24: 07.02.2026 | O24: 09.02.2026 | R24: YES
A25: 24 | B25: 7376231CS329 | C25: =IFERROR(__xludf.DUMMYFUNCTION("XLOOKUP(B25, IMPORTRANGE(""https://docs.google.com/spreadsheets/d/1UUC6R1hVFPCYDEbJMIXaIBW-jeQYiKTRixeKD_tUHGw/edit?gid=0#gid=0"", ""List!B:B""), IMPORTRANGE(""https://docs.google.com/spreadsheets/d/1UUC6R1hVFPCYDEbJMIXaIBW-jeQYiKTRixeKD_tUHGw/edit?gid=0#"&"gid=0"", ""List!C:C""), ""-"")"),"SUWETHA V") -> SUWETHA V | D25: =IFERROR(__xludf.DUMMYFUNCTION("XLOOKUP(B25, IMPORTRANGE(""https://docs.google.com/spreadsheets/d/1UUC6R1hVFPCYDEbJMIXaIBW-jeQYiKTRixeKD_tUHGw/edit?gid=0#gid=0"", ""List!B:B""), IMPORTRANGE(""https://docs.google.com/spreadsheets/d/1UUC6R1hVFPCYDEbJMIXaIBW-jeQYiKTRixeKD_tUHGw/edit?gid=0#"&"gid=0"", ""List!D:D""), ""-"")"),"COMPUTER SCIENCE AND ENGINEERING") -> COMPUTER SCIENCE AND ENGINEERING | E25: Workhall | F25: 5 | G25: Joined | H25: Offline | I25: ITP | J25: Allow for Double the package | K25: =IFERROR(__xludf.DUMMYFUNCTION("XLOOKUP(B25, IMPORTRANGE(""https://docs.google.com/spreadsheets/d/1GpX_8hJc54hBz8KrakqcWdiXAS6pjY1zWE_9fWBXnEM/edit?gid=1460649486#gid=1460649486"", ""List!B:B""), IMPORTRANGE(""https://docs.google.com/spreadsheets/d/1GpX_8hJc54hBz8KrakqcWdiXAS6pjY1zWE_9f"&"WBXnEM/edit?gid=1460649486#gid=1460649486"", ""List!E:E""), ""-"")"),"suwetha.cs23@bitsathy.ac.in") -> suwetha.cs23@bitsathy.ac.in | L25: =IFERROR(__xludf.DUMMYFUNCTION("XLOOKUP(B25, IMPORTRANGE(""https://docs.google.com/spreadsheets/d/1GpX_8hJc54hBz8KrakqcWdiXAS6pjY1zWE_9fWBXnEM/edit?gid=1460649486#gid=1460649486"", ""List!B:B""), IMPORTRANGE(""https://docs.google.com/spreadsheets/d/1GpX_8hJc54hBz8KrakqcWdiXAS6pjY1zWE_9f"&"WBXnEM/edit?gid=1460649486#gid=1460649486"", ""List!G:G""), ""-"")"),"9994770979") -> 9994770979 | M25: T&P | N25: 07.02.2026 | O25: 09.02.2026 | R25: YES
A26: 25 | B26: 7376231EC106 | C26: =IFERROR(__xludf.DUMMYFUNCTION("XLOOKUP(B26, IMPORTRANGE(""https://docs.google.com/spreadsheets/d/1UUC6R1hVFPCYDEbJMIXaIBW-jeQYiKTRixeKD_tUHGw/edit?gid=0#gid=0"", ""List!B:B""), IMPORTRANGE(""https://docs.google.com/spreadsheets/d/1UUC6R1hVFPCYDEbJMIXaIBW-jeQYiKTRixeKD_tUHGw/edit?gid=0#"&"gid=0"", ""List!C:C""), ""-"")"),"AHMED ABU HURAIRAH M H") -> AHMED ABU HURAIRAH M H | D26: =IFERROR(__xludf.DUMMYFUNCTION("XLOOKUP(B26, IMPORTRANGE(""https://docs.google.com/spreadsheets/d/1UUC6R1hVFPCYDEbJMIXaIBW-jeQYiKTRixeKD_tUHGw/edit?gid=0#gid=0"", ""List!B:B""), IMPORTRANGE(""https://docs.google.com/spreadsheets/d/1UUC6R1hVFPCYDEbJMIXaIBW-jeQYiKTRixeKD_tUHGw/edit?gid=0#"&"gid=0"", ""List!D:D""), ""-"")"),"ELECTRONICS AND COMMUNICATION ENGINEERING") -> ELECTRONICS AND COMMUNICATION ENGINEERING | E26: Workhall | F26: 5 | G26: Joined | H26: Offline | I26: ITP | J26: Allow for Double the package | K26: =IFERROR(__xludf.DUMMYFUNCTION("XLOOKUP(B26, IMPORTRANGE(""https://docs.google.com/spreadsheets/d/1GpX_8hJc54hBz8KrakqcWdiXAS6pjY1zWE_9fWBXnEM/edit?gid=1460649486#gid=1460649486"", ""List!B:B""), IMPORTRANGE(""https://docs.google.com/spreadsheets/d/1GpX_8hJc54hBz8KrakqcWdiXAS6pjY1zWE_9f"&"WBXnEM/edit?gid=1460649486#gid=1460649486"", ""List!E:E""), ""-"")"),"ahmedabuhurairah.ec23@bitsathy.ac.in") -> ahmedabuhurairah.ec23@bitsathy.ac.in | L26: =IFERROR(__xludf.DUMMYFUNCTION("XLOOKUP(B26, IMPORTRANGE(""https://docs.google.com/spreadsheets/d/1GpX_8hJc54hBz8KrakqcWdiXAS6pjY1zWE_9fWBXnEM/edit?gid=1460649486#gid=1460649486"", ""List!B:B""), IMPORTRANGE(""https://docs.google.com/spreadsheets/d/1GpX_8hJc54hBz8KrakqcWdiXAS6pjY1zWE_9f"&"WBXnEM/edit?gid=1460649486#gid=1460649486"", ""List!G:G""), ""-"")"),"7010719460") -> 7010719460 | M26: T&P | N26: 07.02.2026 | O26: 09.02.2026 | R26: YES
A27: 26 | B27: 7376232IT203 | C27: =IFERROR(__xludf.DUMMYFUNCTION("XLOOKUP(B27, IMPORTRANGE(""https://docs.google.com/spreadsheets/d/1UUC6R1hVFPCYDEbJMIXaIBW-jeQYiKTRixeKD_tUHGw/edit?gid=0#gid=0"", ""List!B:B""), IMPORTRANGE(""https://docs.google.com/spreadsheets/d/1UUC6R1hVFPCYDEbJMIXaIBW-jeQYiKTRixeKD_tUHGw/edit?gid=0#"&"gid=0"", ""List!C:C""), ""-"")"),"MOHITH M") -> MOHITH M | D27: =IFERROR(__xludf.DUMMYFUNCTION("XLOOKUP(B27, IMPORTRANGE(""https://docs.google.com/spreadsheets/d/1UUC6R1hVFPCYDEbJMIXaIBW-jeQYiKTRixeKD_tUHGw/edit?gid=0#gid=0"", ""List!B:B""), IMPORTRANGE(""https://docs.google.com/spreadsheets/d/1UUC6R1hVFPCYDEbJMIXaIBW-jeQYiKTRixeKD_tUHGw/edit?gid=0#"&"gid=0"", ""List!D:D""), ""-"")"),"INFORMATION TECHNOLOGY") -> INFORMATION TECHNOLOGY | E27: Workhall | F27: 5 | G27: Joined | H27: Offline | I27: ITP | J27: Allow for Double the package | K27: =IFERROR(__xludf.DUMMYFUNCTION("XLOOKUP(B27, IMPORTRANGE(""https://docs.google.com/spreadsheets/d/1GpX_8hJc54hBz8KrakqcWdiXAS6pjY1zWE_9fWBXnEM/edit?gid=1460649486#gid=1460649486"", ""List!B:B""), IMPORTRANGE(""https://docs.google.com/spreadsheets/d/1GpX_8hJc54hBz8KrakqcWdiXAS6pjY1zWE_9f"&"WBXnEM/edit?gid=1460649486#gid=1460649486"", ""List!E:E""), ""-"")"),"mohith.it23@bitsathy.ac.in") -> mohith.it23@bitsathy.ac.in | L27: =IFERROR(__xludf.DUMMYFUNCTION("XLOOKUP(B27, IMPORTRANGE(""https://docs.google.com/spreadsheets/d/1GpX_8hJc54hBz8KrakqcWdiXAS6pjY1zWE_9fWBXnEM/edit?gid=1460649486#gid=1460649486"", ""List!B:B""), IMPORTRANGE(""https://docs.google.com/spreadsheets/d/1GpX_8hJc54hBz8KrakqcWdiXAS6pjY1zWE_9f"&"WBXnEM/edit?gid=1460649486#gid=1460649486"", ""List!G:G""), ""-"")"),"9025646624") -> 9025646624 | M27: T&P | N27: 07.02.2026 | O27: 09.02.2026 | R27: YES
A28: 27 | B28: 7376231CS347 | C28: =IFERROR(__xludf.DUMMYFUNCTION("XLOOKUP(B28, IMPORTRANGE(""https://docs.google.com/spreadsheets/d/1UUC6R1hVFPCYDEbJMIXaIBW-jeQYiKTRixeKD_tUHGw/edit?gid=0#gid=0"", ""List!B:B""), IMPORTRANGE(""https://docs.google.com/spreadsheets/d/1UUC6R1hVFPCYDEbJMIXaIBW-jeQYiKTRixeKD_tUHGw/edit?gid=0#"&"gid=0"", ""List!C:C""), ""-"")"),"VINITHA P") -> VINITHA P | D28: =IFERROR(__xludf.DUMMYFUNCTION("XLOOKUP(B28, IMPORTRANGE(""https://docs.google.com/spreadsheets/d/1UUC6R1hVFPCYDEbJMIXaIBW-jeQYiKTRixeKD_tUHGw/edit?gid=0#gid=0"", ""List!B:B""), IMPORTRANGE(""https://docs.google.com/spreadsheets/d/1UUC6R1hVFPCYDEbJMIXaIBW-jeQYiKTRixeKD_tUHGw/edit?gid=0#"&"gid=0"", ""List!D:D""), ""-"")"),"COMPUTER SCIENCE AND ENGINEERING") -> COMPUTER SCIENCE AND ENGINEERING | E28: Workhall | F28: 5 | G28: Joined | H28: Offline | I28: ITP | J28: Block | K28: =IFERROR(__xludf.DUMMYFUNCTION("XLOOKUP(B28, IMPORTRANGE(""https://docs.google.com/spreadsheets/d/1GpX_8hJc54hBz8KrakqcWdiXAS6pjY1zWE_9fWBXnEM/edit?gid=1460649486#gid=1460649486"", ""List!B:B""), IMPORTRANGE(""https://docs.google.com/spreadsheets/d/1GpX_8hJc54hBz8KrakqcWdiXAS6pjY1zWE_9f"&"WBXnEM/edit?gid=1460649486#gid=1460649486"", ""List!E:E""), ""-"")"),"vinitha.cs23@bitsathy.ac.in") -> vinitha.cs23@bitsathy.ac.in | L28: =IFERROR(__xludf.DUMMYFUNCTION("XLOOKUP(B28, IMPORTRANGE(""https://docs.google.com/spreadsheets/d/1GpX_8hJc54hBz8KrakqcWdiXAS6pjY1zWE_9fWBXnEM/edit?gid=1460649486#gid=1460649486"", ""List!B:B""), IMPORTRANGE(""https://docs.google.com/spreadsheets/d/1GpX_8hJc54hBz8KrakqcWdiXAS6pjY1zWE_9f"&"WBXnEM/edit?gid=1460649486#gid=1460649486"", ""List!G:G""), ""-"")"),"8610203559") -> 8610203559 | M28: T&P | N28: 07.02.2026 | O28: 09.02.2026 | R28: YES
A29: 28 | B29: 7376231CS345 | C29: =IFERROR(__xludf.DUMMYFUNCTION("XLOOKUP(B29, IMPORTRANGE(""https://docs.google.com/spreadsheets/d/1UUC6R1hVFPCYDEbJMIXaIBW-jeQYiKTRixeKD_tUHGw/edit?gid=0#gid=0"", ""List!B:B""), IMPORTRANGE(""https://docs.google.com/spreadsheets/d/1UUC6R1hVFPCYDEbJMIXaIBW-jeQYiKTRixeKD_tUHGw/edit?gid=0#"&"gid=0"", ""List!C:C""), ""-"")"),"VIJAY KRISHNAA P") -> VIJAY KRISHNAA P | D29: =IFERROR(__xludf.DUMMYFUNCTION("XLOOKUP(B29, IMPORTRANGE(""https://docs.google.com/spreadsheets/d/1UUC6R1hVFPCYDEbJMIXaIBW-jeQYiKTRixeKD_tUHGw/edit?gid=0#gid=0"", ""List!B:B""), IMPORTRANGE(""https://docs.google.com/spreadsheets/d/1UUC6R1hVFPCYDEbJMIXaIBW-jeQYiKTRixeKD_tUHGw/edit?gid=0#"&"gid=0"", ""List!D:D""), ""-"")"),"COMPUTER SCIENCE AND ENGINEERING") -> COMPUTER SCIENCE AND ENGINEERING | E29: Codemagen | F29: 6 | G29: Joined | I29: ITP | J29: Allow for Double the package | K29: =IFERROR(__xludf.DUMMYFUNCTION("XLOOKUP(B29, IMPORTRANGE(""https://docs.google.com/spreadsheets/d/1GpX_8hJc54hBz8KrakqcWdiXAS6pjY1zWE_9fWBXnEM/edit?gid=1460649486#gid=1460649486"", ""List!B:B""), IMPORTRANGE(""https://docs.google.com/spreadsheets/d/1GpX_8hJc54hBz8KrakqcWdiXAS6pjY1zWE_9f"&"WBXnEM/edit?gid=1460649486#gid=1460649486"", ""List!E:E""), ""-"")"),"vijaykrishnaa.cs23@bitsathy.ac.in") -> vijaykrishnaa.cs23@bitsathy.ac.in | L29: =IFERROR(__xludf.DUMMYFUNCTION("XLOOKUP(B29, IMPORTRANGE(""https://docs.google.com/spreadsheets/d/1GpX_8hJc54hBz8KrakqcWdiXAS6pjY1zWE_9fWBXnEM/edit?gid=1460649486#gid=1460649486"", ""List!B:B""), IMPORTRANGE(""https://docs.google.com/spreadsheets/d/1GpX_8hJc54hBz8KrakqcWdiXAS6pjY1zWE_9f"&"WBXnEM/edit?gid=1460649486#gid=1460649486"", ""List!G:G""), ""-"")"),"9025287330") -> 9025287330 | M29: T&P | N29: 24.02.2026 | O29: 02.03.2026
A30: 29 | B30: 7376231CS128 | C30: =IFERROR(__xludf.DUMMYFUNCTION("XLOOKUP(B30, IMPORTRANGE(""https://docs.google.com/spreadsheets/d/1UUC6R1hVFPCYDEbJMIXaIBW-jeQYiKTRixeKD_tUHGw/edit?gid=0#gid=0"", ""List!B:B""), IMPORTRANGE(""https://docs.google.com/spreadsheets/d/1UUC6R1hVFPCYDEbJMIXaIBW-jeQYiKTRixeKD_tUHGw/edit?gid=0#"&"gid=0"", ""List!C:C""), ""-"")"),"DAKSHATA R") -> DAKSHATA R | D30: =IFERROR(__xludf.DUMMYFUNCTION("XLOOKUP(B30, IMPORTRANGE(""https://docs.google.com/spreadsheets/d/1UUC6R1hVFPCYDEbJMIXaIBW-jeQYiKTRixeKD_tUHGw/edit?gid=0#gid=0"", ""List!B:B""), IMPORTRANGE(""https://docs.google.com/spreadsheets/d/1UUC6R1hVFPCYDEbJMIXaIBW-jeQYiKTRixeKD_tUHGw/edit?gid=0#"&"gid=0"", ""List!D:D""), ""-"")"),"COMPUTER SCIENCE AND ENGINEERING") -> COMPUTER SCIENCE AND ENGINEERING | E30: EQREV | F30: 5 | G30: Joined | I30: ITP | J30: Allow for Double the package | K30: =IFERROR(__xludf.DUMMYFUNCTION("XLOOKUP(B30, IMPORTRANGE(""https://docs.google.com/spreadsheets/d/1GpX_8hJc54hBz8KrakqcWdiXAS6pjY1zWE_9fWBXnEM/edit?gid=1460649486#gid=1460649486"", ""List!B:B""), IMPORTRANGE(""https://docs.google.com/spreadsheets/d/1GpX_8hJc54hBz8KrakqcWdiXAS6pjY1zWE_9f"&"WBXnEM/edit?gid=1460649486#gid=1460649486"", ""List!E:E""), ""-"")"),"dakshata.cs23@bitsathy.ac.in") -> dakshata.cs23@bitsathy.ac.in | L30: =IFERROR(__xludf.DUMMYFUNCTION("XLOOKUP(B30, IMPORTRANGE(""https://docs.google.com/spreadsheets/d/1GpX_8hJc54hBz8KrakqcWdiXAS6pjY1zWE_9fWBXnEM/edit?gid=1460649486#gid=1460649486"", ""List!B:B""), IMPORTRANGE(""https://docs.google.com/spreadsheets/d/1GpX_8hJc54hBz8KrakqcWdiXAS6pjY1zWE_9f"&"WBXnEM/edit?gid=1460649486#gid=1460649486"", ""List!G:G""), ""-"")"),"8344831834") -> 8344831834 | M30: T&P | N30: 24.02.2026 | O30: 02.03.2026 | V30: DAKSHATA.pdf
A31: 30 | B31: 7376232FT108 | C31: =IFERROR(__xludf.DUMMYFUNCTION("XLOOKUP(B31, IMPORTRANGE(""https://docs.google.com/spreadsheets/d/1UUC6R1hVFPCYDEbJMIXaIBW-jeQYiKTRixeKD_tUHGw/edit?gid=0#gid=0"", ""List!B:B""), IMPORTRANGE(""https://docs.google.com/spreadsheets/d/1UUC6R1hVFPCYDEbJMIXaIBW-jeQYiKTRixeKD_tUHGw/edit?gid=0#"&"gid=0"", ""List!C:C""), ""-"")"),"KEERTHANA K") -> KEERTHANA K | D31: =IFERROR(__xludf.DUMMYFUNCTION("XLOOKUP(B31, IMPORTRANGE(""https://docs.google.com/spreadsheets/d/1UUC6R1hVFPCYDEbJMIXaIBW-jeQYiKTRixeKD_tUHGw/edit?gid=0#gid=0"", ""List!B:B""), IMPORTRANGE(""https://docs.google.com/spreadsheets/d/1UUC6R1hVFPCYDEbJMIXaIBW-jeQYiKTRixeKD_tUHGw/edit?gid=0#"&"gid=0"", ""List!D:D""), ""-"")"),"FASHION TECHNOLOGY") -> FASHION TECHNOLOGY | E31: RSJ Inspection | F31: 3 | G31: Joined | H31: Offline | I31: CORE | J31: Allow for Double the package | K31: =IFERROR(__xludf.DUMMYFUNCTION("XLOOKUP(B31, IMPORTRANGE(""https://docs.google.com/spreadsheets/d/1GpX_8hJc54hBz8KrakqcWdiXAS6pjY1zWE_9fWBXnEM/edit?gid=1460649486#gid=1460649486"", ""List!B:B""), IMPORTRANGE(""https://docs.google.com/spreadsheets/d/1GpX_8hJc54hBz8KrakqcWdiXAS6pjY1zWE_9f"&"WBXnEM/edit?gid=1460649486#gid=1460649486"", ""List!E:E""), ""-"")"),"keerthana.ft23@bitsathy.ac.in") -> keerthana.ft23@bitsathy.ac.in | L31: =IFERROR(__xludf.DUMMYFUNCTION("XLOOKUP(B31, IMPORTRANGE(""https://docs.google.com/spreadsheets/d/1GpX_8hJc54hBz8KrakqcWdiXAS6pjY1zWE_9fWBXnEM/edit?gid=1460649486#gid=1460649486"", ""List!B:B""), IMPORTRANGE(""https://docs.google.com/spreadsheets/d/1GpX_8hJc54hBz8KrakqcWdiXAS6pjY1zWE_9f"&"WBXnEM/edit?gid=1460649486#gid=1460649486"", ""List!G:G""), ""-"")"),"9025686243") -> 9025686243 | M31: T&P | N31: 28.02.2026 | O31: 05.03.2026
A32: 31 | B32: 7376232FT111 | C32: =IFERROR(__xludf.DUMMYFUNCTION("XLOOKUP(B32, IMPORTRANGE(""https://docs.google.com/spreadsheets/d/1UUC6R1hVFPCYDEbJMIXaIBW-jeQYiKTRixeKD_tUHGw/edit?gid=0#gid=0"", ""List!B:B""), IMPORTRANGE(""https://docs.google.com/spreadsheets/d/1UUC6R1hVFPCYDEbJMIXaIBW-jeQYiKTRixeKD_tUHGw/edit?gid=0#"&"gid=0"", ""List!C:C""), ""-"")"),"MANISHA A") -> MANISHA A | D32: =IFERROR(__xludf.DUMMYFUNCTION("XLOOKUP(B32, IMPORTRANGE(""https://docs.google.com/spreadsheets/d/1UUC6R1hVFPCYDEbJMIXaIBW-jeQYiKTRixeKD_tUHGw/edit?gid=0#gid=0"", ""List!B:B""), IMPORTRANGE(""https://docs.google.com/spreadsheets/d/1UUC6R1hVFPCYDEbJMIXaIBW-jeQYiKTRixeKD_tUHGw/edit?gid=0#"&"gid=0"", ""List!D:D""), ""-"")"),"FASHION TECHNOLOGY") -> FASHION TECHNOLOGY | E32: RSJ Inspection | F32: 3 | G32: Joined | H32: Offline | I32: CORE | J32: Allow for Double the package | K32: =IFERROR(__xludf.DUMMYFUNCTION("XLOOKUP(B32, IMPORTRANGE(""https://docs.google.com/spreadsheets/d/1GpX_8hJc54hBz8KrakqcWdiXAS6pjY1zWE_9fWBXnEM/edit?gid=1460649486#gid=1460649486"", ""List!B:B""), IMPORTRANGE(""https://docs.google.com/spreadsheets/d/1GpX_8hJc54hBz8KrakqcWdiXAS6pjY1zWE_9f"&"WBXnEM/edit?gid=1460649486#gid=1460649486"", ""List!E:E""), ""-"")"),"manisha.ft23@bitsathy.ac.in") -> manisha.ft23@bitsathy.ac.in | L32: =IFERROR(__xludf.DUMMYFUNCTION("XLOOKUP(B32, IMPORTRANGE(""https://docs.google.com/spreadsheets/d/1GpX_8hJc54hBz8KrakqcWdiXAS6pjY1zWE_9fWBXnEM/edit?gid=1460649486#gid=1460649486"", ""List!B:B""), IMPORTRANGE(""https://docs.google.com/spreadsheets/d/1GpX_8hJc54hBz8KrakqcWdiXAS6pjY1zWE_9f"&"WBXnEM/edit?gid=1460649486#gid=1460649486"", ""List!G:G""), ""-"")"),"7200616146") -> 7200616146 | M32: T&P | N32: 28.02.2026 | O32: 05.03.2026
A33: 32 | B33: 7376232FT117 | C33: =IFERROR(__xludf.DUMMYFUNCTION("XLOOKUP(B33, IMPORTRANGE(""https://docs.google.com/spreadsheets/d/1UUC6R1hVFPCYDEbJMIXaIBW-jeQYiKTRixeKD_tUHGw/edit?gid=0#gid=0"", ""List!B:B""), IMPORTRANGE(""https://docs.google.com/spreadsheets/d/1UUC6R1hVFPCYDEbJMIXaIBW-jeQYiKTRixeKD_tUHGw/edit?gid=0#"&"gid=0"", ""List!C:C""), ""-"")"),"SARVIKA M K") -> SARVIKA M K | D33: =IFERROR(__xludf.DUMMYFUNCTION("XLOOKUP(B33, IMPORTRANGE(""https://docs.google.com/spreadsheets/d/1UUC6R1hVFPCYDEbJMIXaIBW-jeQYiKTRixeKD_tUHGw/edit?gid=0#gid=0"", ""List!B:B""), IMPORTRANGE(""https://docs.google.com/spreadsheets/d/1UUC6R1hVFPCYDEbJMIXaIBW-jeQYiKTRixeKD_tUHGw/edit?gid=0#"&"gid=0"", ""List!D:D""), ""-"")"),"FASHION TECHNOLOGY") -> FASHION TECHNOLOGY | E33: RSJ Inspection | F33: 3 | G33: Joined | H33: Offline | I33: CORE | J33: Allow for Double the package | K33: =IFERROR(__xludf.DUMMYFUNCTION("XLOOKUP(B33, IMPORTRANGE(""https://docs.google.com/spreadsheets/d/1GpX_8hJc54hBz8KrakqcWdiXAS6pjY1zWE_9fWBXnEM/edit?gid=1460649486#gid=1460649486"", ""List!B:B""), IMPORTRANGE(""https://docs.google.com/spreadsheets/d/1GpX_8hJc54hBz8KrakqcWdiXAS6pjY1zWE_9f"&"WBXnEM/edit?gid=1460649486#gid=1460649486"", ""List!E:E""), ""-"")"),"sarvika.ft23@bitsathy.ac.in") -> sarvika.ft23@bitsathy.ac.in | L33: =IFERROR(__xludf.DUMMYFUNCTION("XLOOKUP(B33, IMPORTRANGE(""https://docs.google.com/spreadsheets/d/1GpX_8hJc54hBz8KrakqcWdiXAS6pjY1zWE_9fWBXnEM/edit?gid=1460649486#gid=1460649486"", ""List!B:B""), IMPORTRANGE(""https://docs.google.com/spreadsheets/d/1GpX_8hJc54hBz8KrakqcWdiXAS6pjY1zWE_9f"&"WBXnEM/edit?gid=1460649486#gid=1460649486"", ""List!G:G""), ""-"")"),"9344517848") -> 9344517848 | M33: T&P | N33: 28.02.2026 | O33: 05.03.2026
A34: 33 | B34: 7376232FT118 | C34: =IFERROR(__xludf.DUMMYFUNCTION("XLOOKUP(B34, IMPORTRANGE(""https://docs.google.com/spreadsheets/d/1UUC6R1hVFPCYDEbJMIXaIBW-jeQYiKTRixeKD_tUHGw/edit?gid=0#gid=0"", ""List!B:B""), IMPORTRANGE(""https://docs.google.com/spreadsheets/d/1UUC6R1hVFPCYDEbJMIXaIBW-jeQYiKTRixeKD_tUHGw/edit?gid=0#"&"gid=0"", ""List!C:C""), ""-"")"),"SHREENITHI K G") -> SHREENITHI K G | D34: =IFERROR(__xludf.DUMMYFUNCTION("XLOOKUP(B34, IMPORTRANGE(""https://docs.google.com/spreadsheets/d/1UUC6R1hVFPCYDEbJMIXaIBW-jeQYiKTRixeKD_tUHGw/edit?gid=0#gid=0"", ""List!B:B""), IMPORTRANGE(""https://docs.google.com/spreadsheets/d/1UUC6R1hVFPCYDEbJMIXaIBW-jeQYiKTRixeKD_tUHGw/edit?gid=0#"&"gid=0"", ""List!D:D""), ""-"")"),"FASHION TECHNOLOGY") -> FASHION TECHNOLOGY | E34: RSJ Inspection | F34: 3 | G34: Joined | H34: Offline | I34: CORE | J34: Allow for Double the package | K34: =IFERROR(__xludf.DUMMYFUNCTION("XLOOKUP(B34, IMPORTRANGE(""https://docs.google.com/spreadsheets/d/1GpX_8hJc54hBz8KrakqcWdiXAS6pjY1zWE_9fWBXnEM/edit?gid=1460649486#gid=1460649486"", ""List!B:B""), IMPORTRANGE(""https://docs.google.com/spreadsheets/d/1GpX_8hJc54hBz8KrakqcWdiXAS6pjY1zWE_9f"&"WBXnEM/edit?gid=1460649486#gid=1460649486"", ""List!E:E""), ""-"")"),"shreenithi.ft23@bitsathy.ac.in") -> shreenithi.ft23@bitsathy.ac.in | L34: =IFERROR(__xludf.DUMMYFUNCTION("XLOOKUP(B34, IMPORTRANGE(""https://docs.google.com/spreadsheets/d/1GpX_8hJc54hBz8KrakqcWdiXAS6pjY1zWE_9fWBXnEM/edit?gid=1460649486#gid=1460649486"", ""List!B:B""), IMPORTRANGE(""https://docs.google.com/spreadsheets/d/1GpX_8hJc54hBz8KrakqcWdiXAS6pjY1zWE_9f"&"WBXnEM/edit?gid=1460649486#gid=1460649486"", ""List!G:G""), ""-"")"),"9842884989") -> 9842884989 | M34: T&P | N34: 28.02.2026 | O34: 05.03.2026
